const x = 2

try{
    x = 4
} catch(err) {
    console.log(err)
}